Workbook

Sheet README
A1: IT Support Ticket Analysis
A2: Author: Maria Antonia Moreno
A4: Objective: identify bottlenecks in IT support and measure SLA compliance, resolution time and customer satisfaction.
A6: Sheets
A7: Tickets – raw ticket log (1,200 tickets, Jan–Jun 2026) + calculated columns (grey headers are formulas).
A8: SLA Policy – resolution-time target per priority (edit these to test other policies).
A9: KPI Summary – formula-driven KPIs by category, priority, team, channel and month, with charts.
A11: Data note: the dataset is SYNTHETIC, generated in Python to mimic a mid-sized company's help desk. It contains no real company or personal data.

Sheet Tickets
A1: Ticket_ID | B1: Created | C1: Resolved | D1: Category | E1: Priority | F1: Channel | G1: Assigned_Team | H1: CSAT | I1: Status | J1: Month | K1: Resolution_Hours | L1: SLA_Target_Hours | M1: SLA_Met
A2: TCK-10001 | B2: 46023.356 | C2: 46024.271 | D2: Hardware | E2: High | F2: Self-Service Portal | G2: Tier 2 - Infrastructure | H2: 3 | I2: =IF(C2="","Open","Resolved") -> Resolved | J2: =TEXT(B2,"yyyy-mm") -> 2026-01 | K2: =IF(C2="","",ROUND((C2-B2)*24,2)) -> 21.97 | L2: =INDEX('SLA Policy'!$B$2:$B$5,MATCH(E2,'SLA Policy'!$A$2:$A$5,0)) -> 8 | M2: =IF(K2="","Open",IF(K2<=L2,"Yes","No")) -> No
A3: TCK-10002 | B3: 46023.464 | C3: 46023.728 | D3: Email | E3: High | F3: Chat | G3: Tier 1 - Service Desk | H3: 5 | I3: =IF(C3="","Open","Resolved") -> Resolved | J3: =TEXT(B3,"yyyy-mm") -> 2026-01 | K3: =IF(C3="","",ROUND((C3-B3)*24,2)) -> 6.35 | L3: =INDEX('SLA Policy'!$B$2:$B$5,MATCH(E3,'SLA Policy'!$A$2:$A$5,0)) -> 8 | M3: =IF(K3="","Open",IF(K3<=L3,"Yes","No")) -> Yes
A4: TCK-10003 | B4: 46023.502 | C4: 46025.888 | D4: Software | E4: Low | F4: Self-Service Portal | G4: Tier 2 - Applications | H4: 3 | I4: =IF(C4="","Open","Resolved") -> Resolved | J4: =TEXT(B4,"yyyy-mm") -> 2026-01 | K4: =IF(C4="","",ROUND((C4-B4)*24,2)) -> 57.27 | L4: =INDEX('SLA Policy'!$B$2:$B$5,MATCH(E4,'SLA Policy'!$A$2:$A$5,0)) -> 72 | M4: =IF(K4="","Open",IF(K4<=L4,"Yes","No")) -> Yes
A5: TCK-10004 | B5: 46023.552 | C5: 46025.306 | D5: Hardware | E5: Medium | F5: Email | G5: Tier 2 - Infrastructure | H5: 4 | I5: =IF(C5="","Open","Resolved") -> Resolved | J5: =TEXT(B5,"yyyy-mm") -> 2026-01 | K5: =IF(C5="","",ROUND((C5-B5)*24,2)) -> 42.1 | L5: =INDEX('SLA Policy'!$B$2:$B$5,MATCH(E5,'SLA Policy'!$A$2:$A$5,0)) -> 24 | M5: =IF(K5="","Open",IF(K5<=L5,"Yes","No")) -> No
A6: TCK-10005 | B6: 46023.636 | C6: 46029.593 | D6: Software | E6: Low | F6: Email | G6: Tier 2 - Applications | H6: 1 | I6: =IF(C6="","Open","Resolved") -> Resolved | J6: =TEXT(B6,"yyyy-mm") -> 2026-01 | K6: =IF(C6="","",ROUND((C6-B6)*24,2)) -> 142.97 | L6: =INDEX('SLA Policy'!$B$2:$B$5,MATCH(E6,'SLA Policy'!$A$2:$A$5,0)) -> 72 | M6: =IF(K6="","Open",IF(K6<=L6,"Yes","No")) -> No
A7: TCK-10006 | B7: 46023.75 | C7: 46030.306 | D7: Hardware | E7: Low | F7: Phone | G7: Tier 2 - Infrastructure | H7: 1 | I7: =IF(C7="","Open","Resolved") -> Resolved | J7: =TEXT(B7,"yyyy-mm") -> 2026-01 | K7: =IF(C7="","",ROUND((C7-B7)*24,2)) -> 157.35 | L7: =INDEX('SLA Policy'!$B$2:$B$5,MATCH(E7,'SLA Policy'!$A$2:$A$5,0)) -> 72 | M7: =IF(K7="","Open",IF(K7<=L7,"Yes","No")) -> No
A8: TCK-10007 | B8: 46023.755 | C8: 46023.941 | D8: Software | E8: Critical | F8: Email | G8: Tier 2 - Applications | H8: 5 | I8: =IF(C8="","Open","Resolved") -> Resolved | J8: =TEXT(B8,"yyyy-mm") -> 2026-01 | K8: =IF(C8="","",ROUND((C8-B8)*24,2)) -> 4.47 | L8: =INDEX('SLA Policy'!$B$2:$B$5,MATCH(E8,'SLA Policy'!$A$2:$A$5,0)) -> 4 | M8: =IF(K8="","Open",IF(K8<=L8,"Yes","No")) -> No
A9: TCK-10008 | B9: 46023.762 | C9: 46024.014 | D9: Access & Accounts | E9: Medium | F9: Phone | G9: Tier 1 - Service Desk | H9: 4 | I9: =IF(C9="","Open","Resolved") -> Resolved | J9: =TEXT(B9,"yyyy-mm") -> 2026-01 | K9: =IF(C9="","",ROUND((C9-B9)*24,2)) -> 6.03 | L9: =INDEX('SLA Policy'!$B$2:$B$5,MATCH(E9,'SLA Policy'!$A$2:$A$5,0)) -> 24 | M9: =IF(K9="","Open",IF(K9<=L9,"Yes","No")) -> Yes
A10: TCK-10009 | B10: 46024.312 | C10: 46024.919 | D10: Access & Accounts | E10: Low | F10: Self-Service Portal | G10: Tier 1 - Service Desk | H10: 4 | I10: =IF(C10="","Open","Resolved") -> Resolved | J10: =TEXT(B10,"yyyy-mm") -> 2026-01 | K10: =IF(C10="","",ROUND((C10-B10)*24,2)) -> 14.55 | L10: =INDEX('SLA Policy'!$B$2:$B$5,MATCH(E10,'SLA Policy'!$A$2:$A$5,0)) -> 72 | M10: =IF(K10="","Open",IF(K10<=L10,"Yes","No")) -> Yes
A11: TCK-10010 | B11: 46024.328 | C11: 46025.512 | D11: Software | E11: Low | F11: Email | G11: Tier 2 - Applications | H11: 4 | I11: =IF(C11="","Open","Resolved") -> Resolved | J11: =TEXT(B11,"yyyy-mm") -> 2026-01 | K11: =IF(C11="","",ROUND((C11-B11)*24,2)) -> 28.4 | L11: =INDEX('SLA Policy'!$B$2:$B$5,MATCH(E11,'SLA Policy'!$A$2:$A$5,0)) -> 72 | M11: =IF(K11="","Open",IF(K11<=L11,"Yes","No")) -> Yes
A12: TCK-10011 | B12: 46024.388 | C12: 46024.88 | D12: Email | E12: Medium | F12: Self-Service Portal | G12: Tier 1 - Service Desk | H12: 5 | I12: =IF(C12="","Open","Resolved") -> Resolved | J12: =TEXT(B12,"yyyy-mm") -> 2026-01 | K12: =IF(C12="","",ROUND((C12-B12)*24,2)) -> 11.8 | L12: =INDEX('SLA Policy'!$B$2:$B$5,MATCH(E12,'SLA Policy'!$A$2:$A$5,0)) -> 24 | M12: =IF(K12="","Open",IF(K12<=L12,"Yes","No")) -> Yes
A13: TCK-10012 | B13: 46024.493 | C13: 46024.626 | D13: Access & Accounts | E13: High | F13: Self-Service Portal | G13: Tier 1 - Service Desk | H13: 5 | I13: =IF(C13="","Open","Resolved") -> Resolved | J13: =TEXT(B13,"yyyy-mm") -> 2026-01 | K13: =IF(C13="","",ROUND((C13-B13)*24,2)) -> 3.2 | L13: =INDEX('SLA Policy'!$B$2:$B$5,MATCH(E13,'SLA Policy'!$A$2:$A$5,0)) -> 8 | M13: =IF(K13="","Open",IF(K13<=L13,"Yes","No")) -> Yes
... A1158: TCK-11157 | B1158: 46196.781 | C1158: 46198.099 | D1158: Network | E1158: Low | F1158: Email | G1158: Tier 2 - Infrastructure | H1158: 4 | I1158: =IF(C1158="","Open","Resolved") -> Resolved | J1158: =TEXT(B1158,"yyyy-mm") -> 2026-06 | K1158: =IF(C1158="","",ROUND((C1158-B1158)*24,2)) -> 31.62 | L1158: =INDEX('SLA Policy'!$B$2:$B$5,MATCH(E1158,'SLA Policy'!$A$2:$A$5,0)) -> 72 | M1158: =IF(K1158="","Open",IF(K1158<=L1158,"Yes","No")) -> Yes
A1159: TCK-11158 | B1159: 46197.308 | D1159: Access & Accounts | E1159: Medium | F1159: Phone | G1159: Tier 1 - Service Desk | I1159: =IF(C1159="","Open","Resolved") -> Open | J1159: =TEXT(B1159,"yyyy-mm") -> 2026-06 | K1159: =IF(C1159="","",ROUND((C1159-B1159)*24,2)) | L1159: =INDEX('SLA Policy'!$B$2:$B$5,MATCH(E1159,'SLA Policy'!$A$2:$A$5,0)) -> 24 | M1159: =IF(K1159="","Open",IF(K1159<=L1159,"Yes","No")) -> Open
A1160: TCK-11159 | B1160: 46197.347 | C1160: 46197.792 | D1160: Access & Accounts | E1160: Medium | F1160: Email | G1160: Tier 1 - Service Desk | H1160: 4 | I1160: =IF(C1160="","Open","Resolved") -> Resolved | J1160: =TEXT(B1160,"yyyy-mm") -> 2026-06 | K1160: =IF(C1160="","",ROUND((C1160-B1160)*24,2)) -> 10.7 | L1160: =INDEX('SLA Policy'!$B$2:$B$5,MATCH(E1160,'SLA Policy'!$A$2:$A$5,0)) -> 24 | M1160: =IF(K1160="","Open",IF(K1160<=L1160,"Yes","No")) -> Yes
A1161: TCK-11160 | B1161: 46197.371 | C1161: 46198.11 | D1161: Access & Accounts | E1161: Low | F1161: Self-Service Portal | G1161: Tier 1 - Service Desk | H1161: 5 | I1161: =IF(C1161="","Open","Resolved") -> Resolved | J1161: =TEXT(B1161,"yyyy-mm") -> 2026-06 | K1161: =IF(C1161="","",ROUND((C1161-B1161)*24,2)) -> 17.73 | L1161: =INDEX('SLA Policy'!$B$2:$B$5,MATCH(E1161,'SLA Policy'!$A$2:$A$5,0)) -> 72 | M1161: =IF(K1161="","Open",IF(K1161<=L1161,"Yes","No")) -> Yes
A1162: TCK-11161 | B1162: 46197.564 | D1162: Access & Accounts | E1162: Medium | F1162: Phone | G1162: Tier 1 - Service Desk | I1162: =IF(C1162="","Open","Resolved") -> Open | J1162: =TEXT(B1162,"yyyy-mm") -> 2026-06 | K1162: =IF(C1162="","",ROUND((C1162-B1162)*24,2)) | L1162: =INDEX('SLA Policy'!$B$2:$B$5,MATCH(E1162,'SLA Policy'!$A$2:$A$5,0)) -> 24 | M1162: =IF(K1162="","Open",IF(K1162<=L1162,"Yes","No")) -> Open
A1163: TCK-11162 | B1163: 46197.742 | D1163: Email | E1163: Critical | F1163: Self-Service Portal | G1163: Tier 1 - Service Desk | I1163: =IF(C1163="","Open","Resolved") -> Open | J1163: =TEXT(B1163,"yyyy-mm") -> 2026-06 | K1163: =IF(C1163="","",ROUND((C1163-B1163)*24,2)) | L1163: =INDEX('SLA Policy'!$B$2:$B$5,MATCH(E1163,'SLA Policy'!$A$2:$A$5,0)) -> 4 | M1163: =IF(K1163="","Open",IF(K1163<=L1163,"Yes","No")) -> Open
A1164: TCK-11163 | B1164: 46198.367 | D1164: Access & Accounts | E1164: Medium | F1164: Email | G1164: Tier 1 - Service Desk | I1164: =IF(C1164="","Open","Resolved") -> Open | J1164: =TEXT(B1164,"yyyy-mm") -> 2026-06 | K1164: =IF(C1164="","",ROUND((C1164-B1164)*24,2)) | L1164: =INDEX('SLA Policy'!$B$2:$B$5,MATCH(E1164,'SLA Policy'!$A$2:$A$5,0)) -> 24 | M1164: =IF(K1164="","Open",IF(K1164<=L1164,"Yes","No")) -> Open
A1165: TCK-11164 | B1165: 46198.399 | D1165: Access & Accounts | E1165: Medium | F1165: Phone | G1165: Tier 1 - Service Desk | I1165: =IF(C1165="","Open","Resolved") -> Open | J1165: =TEXT(B1165,"yyyy-mm") -> 2026-06 | K1165: =IF(C1165="","",ROUND((C1165-B1165)*24,2)) | L1165: =INDEX('SLA Policy'!$B$2:$B$5,MATCH(E1165,'SLA Policy'!$A$2:$A$5,0)) -> 24 | M1165: =IF(K1165="","Open",IF(K1165<=L1165,"Yes","No")) -> Open
A1166: TCK-11165 | B1166: 46198.552 | D1166: Hardware | E1166: Low | F1166: Phone | G1166: Tier 2 - Infrastructure | I1166: =IF(C1166="","Open","Resolved") -> Open | J1166: =TEXT(B1166,"yyyy-mm") -> 2026-06 | K1166: =IF(C1166="","",ROUND((C1166-B1166)*24,2)) | L1166: =INDEX('SLA Policy'!$B$2:$B$5,MATCH(E1166,'SLA Policy'!$A$2:$A$5,0)) -> 72 | M1166: =IF(K1166="","Open",IF(K1166<=L1166,"Yes","No")) -> Open
A1167: TCK-11166 | B1167: 46198.659 | D1167: Access & Accounts | E1167: Medium | F1167: Self-Service Portal | G1167: Tier 1 - Service Desk | I1167: =IF(C1167="","Open","Resolved") -> Open | J1167: =TEXT(B1167,"yyyy-mm") -> 2026-06 | K1167: =IF(C1167="","",ROUND((C1167-B1167)*24,2)) | L1167: =INDEX('SLA Policy'!$B$2:$B$5,MATCH(E1167,'SLA Policy'!$A$2:$A$5,0)) -> 24 | M1167: =IF(K1167="","Open",IF(K1167<=L1167,"Yes","No")) -> Open
A1168: TCK-11167 | B1168: 46198.672 | C1168: 46200.259 | D1168: Software | E1168: Low | F1168: Phone | G1168: Tier 2 - Applications | H1168: 4 | I1168: =IF(C1168="","Open","Resolved") -> Resolved | J1168: =TEXT(B1168,"yyyy-mm") -> 2026-06 | K1168: =IF(C1168="","",ROUND((C1168-B1168)*24,2)) -> 38.08 | L1168: =INDEX('SLA Policy'!$B$2:$B$5,MATCH(E1168,'SLA Policy'!$A$2:$A$5,0)) -> 72 | M1168: =IF(K1168="","Open",IF(K1168<=L1168,"Yes","No")) -> Yes
A1169: TCK-11168 | B1169: 46199.355 | C1169: 46199.709 | D1169: Access & Accounts | E1169: Medium | F1169: Self-Service Portal | G1169: Tier 1 - Service Desk | H1169: 5 | I1169: =IF(C1169="","Open","Resolved") -> Resolved | J1169: =TEXT(B1169,"yyyy-mm") -> 2026-06 | K1169: =IF(C1169="","",ROUND((C1169-B1169)*24,2)) -> 8.5 | L1169: =INDEX('SLA Policy'!$B$2:$B$5,MATCH(E1169,'SLA Policy'!$A$2:$A$5,0)) -> 24 | M1169: =IF(K1169="","Open",IF(K1169<=L1169,"Yes","No")) -> Yes
A1170: TCK-11169 | B1170: 46199.417 | C1170: 46200.287 | D1170: Email | E1170: Medium | F1170: Self-Service Portal | G1170: Tier 1 - Service Desk | H1170: 4 | I1170: =IF(C1170="","Open","Resolved") -> Resolved | J1170: =TEXT(B1170,"yyyy-mm") -> 2026-06 | K1170: =IF(C1170="","",ROUND((C1170-B1170)*24,2)) -> 20.88 | L1170: =INDEX('SLA Policy'!$B$2:$B$5,MATCH(E1170,'SLA Policy'!$A$2:$A$5,0)) -> 24 | M1170: =IF(K1170="","Open",IF(K1170<=L1170,"Yes","No")) -> Yes
A1171: TCK-11170 | B1171: 46199.48 | D1171: Access & Accounts | E1171: Medium | F1171: Self-Service Portal | G1171: Tier 1 - Service Desk | I1171: =IF(C1171="","Open","Resolved") -> Open | J1171: =TEXT(B1171,"yyyy-mm") -> 2026-06 | K1171: =IF(C1171="","",ROUND((C1171-B1171)*24,2)) | L1171: =INDEX('SLA Policy'!$B$2:$B$5,MATCH(E1171,'SLA Policy'!$A$2:$A$5,0)) -> 24 | M1171: =IF(K1171="","Open",IF(K1171<=L1171,"Yes","No")) -> Open
A1172: TCK-11171 | B1172: 46199.49 | D1172: Software | E1172: Low | F1172: Email | G1172: Tier 2 - Applications | I1172: =IF(C1172="","Open","Resolved") -> Open | J1172: =TEXT(B1172,"yyyy-mm") -> 2026-06 | K1172: =IF(C1172="","",ROUND((C1172-B1172)*24,2)) | L1172: =INDEX('SLA Policy'!$B$2:$B$5,MATCH(E1172,'SLA Policy'!$A$2:$A$5,0)) -> 72 | M1172: =IF(K1172="","Open",IF(K1172<=L1172,"Yes","No")) -> Open
A1173: TCK-11172 | B1173: 46199.496 | D1173: Software | E1173: High | F1173: Self-Service Portal | G1173: Tier 2 - Applications | I1173: =IF(C1173="","Open","Resolved") -> Open | J1173: =TEXT(B1173,"yyyy-mm") -> 2026-06 | K1173: =IF(C1173="","",ROUND((C1173-B1173)*24,2)) | L1173: =INDEX('SLA Policy'!$B$2:$B$5,MATCH(E1173,'SLA Policy'!$A$2:$A$5,0)) -> 8 | M1173: =IF(K1173="","Open",IF(K1173<=L1173,"Yes","No")) -> Open
A1174: TCK-11173 | B1174: 46199.54 | D1174: Email | E1174: Medium | F1174: Email | G1174: Tier 1 - Service Desk | I1174: =IF(C1174="","Open","Resolved") -> Open | J1174: =TEXT(B1174,"yyyy-mm") -> 2026-06 | K1174: =IF(C1174="","",ROUND((C1174-B1174)*24,2)) | L1174: =INDEX('SLA Policy'!$B$2:$B$5,MATCH(E1174,'SLA Policy'!$A$2:$A$5,0)) -> 24 | M1174: =IF(K1174="","Open",IF(K1174<=L1174,"Yes","No")) -> Open
A1175: TCK-11174 | B1175: 46199.576 | C1175: 46199.877 | D1175: Access & Accounts | E1175: Medium | F1175: Phone | G1175: Tier 1 - Service Desk | H1175: 5 | I1175: =IF(C1175="","Open","Resolved") -> Resolved | J1175: =TEXT(B1175,"yyyy-mm") -> 2026-06 | K1175: =IF(C1175="","",ROUND((C1175-B1175)*24,2)) -> 7.22 | L1175: =INDEX('SLA Policy'!$B$2:$B$5,MATCH(E1175,'SLA Policy'!$A$2:$A$5,0)) -> 24 | M1175: =IF(K1175="","Open",IF(K1175<=L1175,"Yes","No")) -> Yes
A1176: TCK-11175 | B1176: 46199.603 | C1176: 46199.878 | D1176: Access & Accounts | E1176: Medium | F1176: Phone | G1176: Tier 1 - Service Desk | H1176: 3 | I1176: =IF(C1176="","Open","Resolved") -> Resolved | J1176: =TEXT(B1176,"yyyy-mm") -> 2026-06 | K1176: =IF(C1176="","",ROUND((C1176-B1176)*24,2)) -> 6.6 | L1176: =INDEX('SLA Policy'!$B$2:$B$5,MATCH(E1176,'SLA Policy'!$A$2:$A$5,0)) -> 24 | M1176: =IF(K1176="","Open",IF(K1176<=L1176,"Yes","No")) -> Yes
A1177: TCK-11176 | B1177: 46199.727 | D1177: Software | E1177: Medium | F1177: Self-Service Portal | G1177: Tier 2 - Applications | I1177: =IF(C1177="","Open","Resolved") -> Open | J1177: =TEXT(B1177,"yyyy-mm") -> 2026-06 | K1177: =IF(C1177="","",ROUND((C1177-B1177)*24,2)) | L1177: =INDEX('SLA Policy'!$B$2:$B$5,MATCH(E1177,'SLA Policy'!$A$2:$A$5,0)) -> 24 | M1177: =IF(K1177="","Open",IF(K1177<=L1177,"Yes","No")) -> Open
A1178: TCK-11177 | B1178: 46199.789 | D1178: Software | E1178: Low | F1178: Self-Service Portal | G1178: Tier 2 - Applications | I1178: =IF(C1178="","Open","Resolved") -> Open | J1178: =TEXT(B1178,"yyyy-mm") -> 2026-06 | K1178: =IF(C1178="","",ROUND((C1178-B1178)*24,2)) | L1178: =INDEX('SLA Policy'!$B$2:$B$5,MATCH(E1178,'SLA Policy'!$A$2:$A$5,0)) -> 72 | M1178: =IF(K1178="","Open",IF(K1178<=L1178,"Yes","No")) -> Open
A1179: TCK-11178 | B1179: 46200.412 | C1179: 46201.501 | D1179: Network | E1179: Medium | F1179: Self-Service Portal | G1179: Tier 2 - Infrastructure | H1179: 4 | I1179: =IF(C1179="","Open","Resolved") -> Resolved | J1179: =TEXT(B1179,"yyyy-mm") -> 2026-06 | K1179: =IF(C1179="","",ROUND((C1179-B1179)*24,2)) -> 26.12 | L1179: =INDEX('SLA Policy'!$B$2:$B$5,MATCH(E1179,'SLA Policy'!$A$2:$A$5,0)) -> 24 | M1179: =IF(K1179="","Open",IF(K1179<=L1179,"Yes","No")) -> No
A1180: TCK-11179 | B1180: 46200.492 | D1180: Software | E1180: Low | F1180: Email | G1180: Tier 2 - Applications | I1180: =IF(C1180="","Open","Resolved") -> Open | J1180: =TEXT(B1180,"yyyy-mm") -> 2026-06 | K1180: =IF(C1180="","",ROUND((C1180-B1180)*24,2)) | L1180: =INDEX('SLA Policy'!$B$2:$B$5,MATCH(E1180,'SLA Policy'!$A$2:$A$5,0)) -> 72 | M1180: =IF(K1180="","Open",IF(K1180<=L1180,"Yes","No")) -> Open
A1181: TCK-11180 | B1181: 46200.599 | D1181: Hardware | E1181: Low | F1181: Self-Service Portal | G1181: Tier 2 - Infrastructure | I1181: =IF(C1181="","Open","Resolved") -> Open | J1181: =TEXT(B1181,"yyyy-mm") -> 2026-06 | K1181: =IF(C1181="","",ROUND((C1181-B1181)*24,2)) | L1181: =INDEX('SLA Policy'!$B$2:$B$5,MATCH(E1181,'SLA Policy'!$A$2:$A$5,0)) -> 72 | M1181: =IF(K1181="","Open",IF(K1181<=L1181,"Yes","No")) -> Open
A1182: TCK-11181 | B1182: 46200.654 | C1182: 46201.085 | D1182: Access & Accounts | E1182: High | F1182: Email | G1182: Tier 1 - Service Desk | H1182: 4 | I1182: =IF(C1182="","Open","Resolved") -> Resolved | J1182: =TEXT(B1182,"yyyy-mm") -> 2026-06 | K1182: =IF(C1182="","",ROUND((C1182-B1182)*24,2)) -> 10.33 | L1182: =INDEX('SLA Policy'!$B$2:$B$5,MATCH(E1182,'SLA Policy'!$A$2:$A$5,0)) -> 8 | M1182: =IF(K1182="","Open",IF(K1182<=L1182,"Yes","No")) -> No
A1183: TCK-11182 | B1183: 46201.347 | D1183: Access & Accounts | E1183: Low | F1183: Chat | G1183: Tier 1 - Service Desk | I1183: =IF(C1183="","Open","Resolved") -> Open | J1183: =TEXT(B1183,"yyyy-mm") -> 2026-06 | K1183: =IF(C1183="","",ROUND((C1183-B1183)*24,2)) | L1183: =INDEX('SLA Policy'!$B$2:$B$5,MATCH(E1183,'SLA Policy'!$A$2:$A$5,0)) -> 72 | M1183: =IF(K1183="","Open",IF(K1183<=L1183,"Yes","No")) -> Open
A1184: TCK-11183 | B1184: 46202.331 | D1184: Access & Accounts | E1184: Medium | F1184: Chat | G1184: Tier 1 - Service Desk | I1184: =IF(C1184="","Open","Resolved") -> Open | J1184: =TEXT(B1184,"yyyy-mm") -> 2026-06 | K1184: =IF(C1184="","",ROUND((C1184-B1184)*24,2)) | L1184: =INDEX('SLA Policy'!$B$2:$B$5,MATCH(E1184,'SLA Policy'!$A$2:$A$5,0)) -> 24 | M1184: =IF(K1184="","Open",IF(K1184<=L1184,"Yes","No")) -> Open
...

Sheet KPI Summary
A1: IT Support KPI Summary (Jan–Jun 2026)
A3: Headline KPIs
A4: Total tickets | B4: =COUNTA(Tickets!$A$2:$A$1201) -> 1200
A5: Open tickets | B5: =COUNTIF(Tickets!$I$2:$I$1201,"Open") -> 27
A6: Avg resolution time (hrs) | B6: =AVERAGE(Tickets!$K$2:$K$1201) -> 28.563342
A7: Median resolution time (hrs) | B7: =MEDIAN(Tickets!$K$2:$K$1201) -> 18.53
A8: SLA compliance % | B8: =COUNTIF(Tickets!$M$2:$M$1201,"Yes")/(COUNTIF(Tickets!$M$2:$M$1201,"Yes")+COUNTIF(Tickets!$M$2:$M$1201,"No")) -> 0.64450128
A9: Avg CSAT (1–5) | B9: =AVERAGE(Tickets!$H$2:$H$1201) -> 3.8635976
A11: Category | B11: Tickets | C11: % of Total | D11: Avg Resolution (hrs) | E11: SLA Met | F11: SLA Breached | G11: SLA Compliance % | H11: Avg CSAT
A12: Access & Accounts | B12: =COUNTIF(Tickets!$D$2:$D$1201,$A12) -> 290 | C12: =B12/$B$4 -> 0.24166667 | D12: =IFERROR(AVERAGEIFS(Tickets!$K$2:$K$1201,Tickets!$D$2:$D$1201,$A12),0) -> 13.58405 | E12: =COUNTIFS(Tickets!$D$2:$D$1201,$A12,Tickets!$M$2:$M$1201,"Yes") -> 266 | F12: =COUNTIFS(Tickets!$D$2:$D$1201,$A12,Tickets!$M$2:$M$1201,"No") -> 13 | G12: =IFERROR(E12/(E12+F12),0) -> 0.95340502 | H12: =IFERROR(AVERAGEIFS(Tickets!$H$2:$H$1201,Tickets!$D$2:$D$1201,$A12),0) -> 4.3799283
A13: Email | B13: =COUNTIF(Tickets!$D$2:$D$1201,$A13) -> 126 | C13: =B13/$B$4 -> 0.105 | D13: =IFERROR(AVERAGEIFS(Tickets!$K$2:$K$1201,Tickets!$D$2:$D$1201,$A13),0) -> 19.314959 | E13: =COUNTIFS(Tickets!$D$2:$D$1201,$A13,Tickets!$M$2:$M$1201,"Yes") -> 97 | F13: =COUNTIFS(Tickets!$D$2:$D$1201,$A13,Tickets!$M$2:$M$1201,"No") -> 26 | G13: =IFERROR(E13/(E13+F13),0) -> 0.78861789 | H13: =IFERROR(AVERAGEIFS(Tickets!$H$2:$H$1201,Tickets!$D$2:$D$1201,$A13),0) -> 4.0569106
A14: Hardware | B14: =COUNTIF(Tickets!$D$2:$D$1201,$A14) -> 207 | C14: =B14/$B$4 -> 0.1725 | D14: =IFERROR(AVERAGEIFS(Tickets!$K$2:$K$1201,Tickets!$D$2:$D$1201,$A14),0) -> 43.440448 | E14: =COUNTIFS(Tickets!$D$2:$D$1201,$A14,Tickets!$M$2:$M$1201,"Yes") -> 67 | F14: =COUNTIFS(Tickets!$D$2:$D$1201,$A14,Tickets!$M$2:$M$1201,"No") -> 134 | G14: =IFERROR(E14/(E14+F14),0) -> 0.33333333 | H14: =IFERROR(AVERAGEIFS(Tickets!$H$2:$H$1201,Tickets!$D$2:$D$1201,$A14),0) -> 3.4875622
A15: Network | B15: =COUNTIF(Tickets!$D$2:$D$1201,$A15) -> 172 | C15: =B15/$B$4 -> 0.14333333 | D15: =IFERROR(AVERAGEIFS(Tickets!$K$2:$K$1201,Tickets!$D$2:$D$1201,$A15),0) -> 51.745029 | E15: =COUNTIFS(Tickets!$D$2:$D$1201,$A15,Tickets!$M$2:$M$1201,"Yes") -> 48 | F15: =COUNTIFS(Tickets!$D$2:$D$1201,$A15,Tickets!$M$2:$M$1201,"No") -> 123 | G15: =IFERROR(E15/(E15+F15),0) -> 0.28070175 | H15: =IFERROR(AVERAGEIFS(Tickets!$H$2:$H$1201,Tickets!$D$2:$D$1201,$A15),0) -> 3.0994152
A16: Software | B16: =COUNTIF(Tickets!$D$2:$D$1201,$A16) -> 405 | C16: =B16/$B$4 -> 0.3375 | D16: =IFERROR(AVERAGEIFS(Tickets!$K$2:$K$1201,Tickets!$D$2:$D$1201,$A16),0) -> 24.459098 | E16: =COUNTIFS(Tickets!$D$2:$D$1201,$A16,Tickets!$M$2:$M$1201,"Yes") -> 278 | F16: =COUNTIFS(Tickets!$D$2:$D$1201,$A16,Tickets!$M$2:$M$1201,"No") -> 121 | G16: =IFERROR(E16/(E16+F16),0) -> 0.69674185 | H16: =IFERROR(AVERAGEIFS(Tickets!$H$2:$H$1201,Tickets!$D$2:$D$1201,$A16),0) -> 3.9598997
A19: Priority | B19: Tickets | C19: % of Total | D19: Avg Resolution (hrs) | E19: SLA Met | F19: SLA Breached | G19: SLA Compliance % | H19: Avg CSAT
A20: Critical | B20: =COUNTIF(Tickets!$E$2:$E$1201,$A20) -> 73 | C20: =B20/$B$4 -> 0.060833333 | D20: =IFERROR(AVERAGEIFS(Tickets!$K$2:$K$1201,Tickets!$E$2:$E$1201,$A20),0) -> 3.7126389 | E20: =COUNTIFS(Tickets!$E$2:$E$1201,$A20,Tickets!$M$2:$M$1201,"Yes") -> 43 | F20: =COUNTIFS(Tickets!$E$2:$E$1201,$A20,Tickets!$M$2:$M$1201,"No") -> 29 | G20: =IFERROR(E20/(E20+F20),0) -> 0.59722222 | H20: =IFERROR(AVERAGEIFS(Tickets!$H$2:$H$1201,Tickets!$E$2:$E$1201,$A20),0) -> 4.6111111
A21: High | B21: =COUNTIF(Tickets!$E$2:$E$1201,$A21) -> 241 | C21: =B21/$B$4 -> 0.20083333 | D21: =IFERROR(AVERAGEIFS(Tickets!$K$2:$K$1201,Tickets!$E$2:$E$1201,$A21),0) -> 9.141308 | E21: =COUNTIFS(Tickets!$E$2:$E$1201,$A21,Tickets!$M$2:$M$1201,"Yes") -> 133 | F21: =COUNTIFS(Tickets!$E$2:$E$1201,$A21,Tickets!$M$2:$M$1201,"No") -> 104 | G21: =IFERROR(E21/(E21+F21),0) -> 0.56118143 | H21: =IFERROR(AVERAGEIFS(Tickets!$H$2:$H$1201,Tickets!$E$2:$E$1201,$A21),0) -> 4.4894515
A22: Medium | B22: =COUNTIF(Tickets!$E$2:$E$1201,$A22) -> 555 | C22: =B22/$B$4 -> 0.4625 | D22: =IFERROR(AVERAGEIFS(Tickets!$K$2:$K$1201,Tickets!$E$2:$E$1201,$A22),0) -> 24.233826 | E22: =COUNTIFS(Tickets!$E$2:$E$1201,$A22,Tickets!$M$2:$M$1201,"Yes") -> 341 | F22: =COUNTIFS(Tickets!$E$2:$E$1201,$A22,Tickets!$M$2:$M$1201,"No") -> 200 | G22: =IFERROR(E22/(E22+F22),0) -> 0.63031423 | H22: =IFERROR(AVERAGEIFS(Tickets!$H$2:$H$1201,Tickets!$E$2:$E$1201,$A22),0) -> 3.9815157
A23: Low | B23: =COUNTIF(Tickets!$E$2:$E$1201,$A23) -> 331 | C23: =B23/$B$4 -> 0.27583333 | D23: =IFERROR(AVERAGEIFS(Tickets!$K$2:$K$1201,Tickets!$E$2:$E$1201,$A23),0) -> 55.605263 | E23: =COUNTIFS(Tickets!$E$2:$E$1201,$A23,Tickets!$M$2:$M$1201,"Yes") -> 239 | F23: =COUNTIFS(Tickets!$E$2:$E$1201,$A23,Tickets!$M$2:$M$1201,"No") -> 84 | G23: =IFERROR(E23/(E23+F23),0) -> 0.73993808 | H23: =IFERROR(AVERAGEIFS(Tickets!$H$2:$H$1201,Tickets!$E$2:$E$1201,$A23),0) -> 3.0402477
A26: Assigned Team | B26: Tickets | C26: % of Total | D26: Avg Resolution (hrs) | E26: SLA Met | F26: SLA Breached | G26: SLA Compliance % | H26: Avg CSAT
A27: Tier 1 - Service Desk | B27: =COUNTIF(Tickets!$G$2:$G$1201,$A27) -> 416 | C27: =B27/$B$4 -> 0.34666667 | D27: =IFERROR(AVERAGEIFS(Tickets!$K$2:$K$1201,Tickets!$G$2:$G$1201,$A27),0) -> 15.337537 | E27: =COUNTIFS(Tickets!$G$2:$G$1201,$A27,Tickets!$M$2:$M$1201,"Yes") -> 363 | F27: =COUNTIFS(Tickets!$G$2:$G$1201,$A27,Tickets!$M$2:$M$1201,"No") -> 39 | G27: =IFERROR(E27/(E27+F27),0) -> 0.90298507 | H27: =IFERROR(AVERAGEIFS(Tickets!$H$2:$H$1201,Tickets!$G$2:$G$1201,$A27),0) -> 4.2810945
A28: Tier 2 - Applications | B28: =COUNTIF(Tickets!$G$2:$G$1201,$A28) -> 405 | C28: =B28/$B$4 -> 0.3375 | D28: =IFERROR(AVERAGEIFS(Tickets!$K$2:$K$1201,Tickets!$G$2:$G$1201,$A28),0) -> 24.459098 | E28: =COUNTIFS(Tickets!$G$2:$G$1201,$A28,Tickets!$M$2:$M$1201,"Yes") -> 278 | F28: =COUNTIFS(Tickets!$G$2:$G$1201,$A28,Tickets!$M$2:$M$1201,"No") -> 121 | G28: =IFERROR(E28/(E28+F28),0) -> 0.69674185 | H28: =IFERROR(AVERAGEIFS(Tickets!$H$2:$H$1201,Tickets!$G$2:$G$1201,$A28),0) -> 3.9598997
A29: Tier 2 - Infrastructure | B29: =COUNTIF(Tickets!$G$2:$G$1201,$A29) -> 379 | C29: =B29/$B$4 -> 0.31583333 | D29: =IFERROR(AVERAGEIFS(Tickets!$K$2:$K$1201,Tickets!$G$2:$G$1201,$A29),0) -> 47.257876 | E29: =COUNTIFS(Tickets!$G$2:$G$1201,$A29,Tickets!$M$2:$M$1201,"Yes") -> 115 | F29: =COUNTIFS(Tickets!$G$2:$G$1201,$A29,Tickets!$M$2:$M$1201,"No") -> 257 | G29: =IFERROR(E29/(E29+F29),0) -> 0.30913978 | H29: =IFERROR(AVERAGEIFS(Tickets!$H$2:$H$1201,Tickets!$G$2:$G$1201,$A29),0) -> 3.3091398
A32: Channel | B32: Tickets | C32: % of Total | D32: Avg Resolution (hrs) | E32: SLA Met | F32: SLA Breached | G32: SLA Compliance % | H32: Avg CSAT
A33: Chat | B33: =COUNTIF(Tickets!$F$2:$F$1201,$A33) -> 170 | C33: =B33/$B$4 -> 0.14166667 | D33: =IFERROR(AVERAGEIFS(Tickets!$K$2:$K$1201,Tickets!$F$2:$F$1201,$A33),0) -> 30.125629 | E33: =COUNTIFS(Tickets!$F$2:$F$1201,$A33,Tickets!$M$2:$M$1201,"Yes") -> 106 | F33: =COUNTIFS(Tickets!$F$2:$F$1201,$A33,Tickets!$M$2:$M$1201,"No") -> 61 | G33: =IFERROR(E33/(E33+F33),0) -> 0.63473054 | H33: =IFERROR(AVERAGEIFS(Tickets!$H$2:$H$1201,Tickets!$F$2:$F$1201,$A33),0) -> 3.7664671
A34: Email | B34: =COUNTIF(Tickets!$F$2:$F$1201,$A34) -> 415 | C34: =B34/$B$4 -> 0.34583333 | D34: =IFERROR(AVERAGEIFS(Tickets!$K$2:$K$1201,Tickets!$F$2:$F$1201,$A34),0) -> 28.025407 | E34: =COUNTIFS(Tickets!$F$2:$F$1201,$A34,Tickets!$M$2:$M$1201,"Yes") -> 263 | F34: =COUNTIFS(Tickets!$F$2:$F$1201,$A34,Tickets!$M$2:$M$1201,"No") -> 142 | G34: =IFERROR(E34/(E34+F34),0) -> 0.64938272 | H34: =IFERROR(AVERAGEIFS(Tickets!$H$2:$H$1201,Tickets!$F$2:$F$1201,$A34),0) -> 3.8962963
A35: Phone | B35: =COUNTIF(Tickets!$F$2:$F$1201,$A35) -> 246 | C35: =B35/$B$4 -> 0.205 | D35: =IFERROR(AVERAGEIFS(Tickets!$K$2:$K$1201,Tickets!$F$2:$F$1201,$A35),0) -> 27.818075 | E35: =COUNTIFS(Tickets!$F$2:$F$1201,$A35,Tickets!$M$2:$M$1201,"Yes") -> 150 | F35: =COUNTIFS(Tickets!$F$2:$F$1201,$A35,Tickets!$M$2:$M$1201,"No") -> 89 | G35: =IFERROR(E35/(E35+F35),0) -> 0.62761506 | H35: =IFERROR(AVERAGEIFS(Tickets!$H$2:$H$1201,Tickets!$F$2:$F$1201,$A35),0) -> 3.8828452
A36: Self-Service Portal | B36: =COUNTIF(Tickets!$F$2:$F$1201,$A36) -> 369 | C36: =B36/$B$4 -> 0.3075 | D36: =IFERROR(AVERAGEIFS(Tickets!$K$2:$K$1201,Tickets!$F$2:$F$1201,$A36),0) -> 28.936492 | E36: =COUNTIFS(Tickets!$F$2:$F$1201,$A36,Tickets!$M$2:$M$1201,"Yes") -> 237 | F36: =COUNTIFS(Tickets!$F$2:$F$1201,$A36,Tickets!$M$2:$M$1201,"No") -> 125 | G36: =IFERROR(E36/(E36+F36),0) -> 0.65469613 | H36: =IFERROR(AVERAGEIFS(Tickets!$H$2:$H$1201,Tickets!$F$2:$F$1201,$A36),0) -> 3.859116
A39: Month | B39: Tickets | C39: % of Total | D39: Avg Resolution (hrs) | E39: SLA Met | F39: SLA Breached | G39: SLA Compliance % | H39: Avg CSAT
A40: 2026-01 | B40: =COUNTIF(Tickets!$J$2:$J$1201,$A40) -> 204 | C40: =B40/$B$4 -> 0.17 | D40: =IFERROR(AVERAGEIFS(Tickets!$K$2:$K$1201,Tickets!$J$2:$J$1201,$A40),0) -> 32.731912 | E40: =COUNTIFS(Tickets!$J$2:$J$1201,$A40,Tickets!$M$2:$M$1201,"Yes") -> 125 | F40: =COUNTIFS(Tickets!$J$2:$J$1201,$A40,Tickets!$M$2:$M$1201,"No") -> 79 | G40: =IFERROR(E40/(E40+F40),0) -> 0.6127451 | H40: =IFERROR(AVERAGEIFS(Tickets!$H$2:$H$1201,Tickets!$J$2:$J$1201,$A40),0) -> 3.8039216
A41: 2026-02 | B41: =COUNTIF(Tickets!$J$2:$J$1201,$A41) -> 155 | C41: =B41/$B$4 -> 0.12916667 | D41: =IFERROR(AVERAGEIFS(Tickets!$K$2:$K$1201,Tickets!$J$2:$J$1201,$A41),0) -> 29.689097 | E41: =COUNTIFS(Tickets!$J$2:$J$1201,$A41,Tickets!$M$2:$M$1201,"Yes") -> 92 | F41: =COUNTIFS(Tickets!$J$2:$J$1201,$A41,Tickets!$M$2:$M$1201,"No") -> 63 | G41: =IFERROR(E41/(E41+F41),0) -> 0.59354839 | H41: =IFERROR(AVERAGEIFS(Tickets!$H$2:$H$1201,Tickets!$J$2:$J$1201,$A41),0) -> 3.7870968
A42: 2026-03 | B42: =COUNTIF(Tickets!$J$2:$J$1201,$A42) -> 292 | C42: =B42/$B$4 -> 0.24333333 | D42: =IFERROR(AVERAGEIFS(Tickets!$K$2:$K$1201,Tickets!$J$2:$J$1201,$A42),0) -> 27.063082 | E42: =COUNTIFS(Tickets!$J$2:$J$1201,$A42,Tickets!$M$2:$M$1201,"Yes") -> 198 | F42: =COUNTIFS(Tickets!$J$2:$J$1201,$A42,Tickets!$M$2:$M$1201,"No") -> 94 | G42: =IFERROR(E42/(E42+F42),0) -> 0.67808219 | H42: =IFERROR(AVERAGEIFS(Tickets!$H$2:$H$1201,Tickets!$J$2:$J$1201,$A42),0) -> 3.9075342
A43: 2026-04 | B43: =COUNTIF(Tickets!$J$2:$J$1201,$A43) -> 176 | C43: =B43/$B$4 -> 0.14666667 | D43: =IFERROR(AVERAGEIFS(Tickets!$K$2:$K$1201,Tickets!$J$2:$J$1201,$A43),0) -> 26.555227 | E43: =COUNTIFS(Tickets!$J$2:$J$1201,$A43,Tickets!$M$2:$M$1201,"Yes") -> 114 | F43: =COUNTIFS(Tickets!$J$2:$J$1201,$A43,Tickets!$M$2:$M$1201,"No") -> 62 | G43: =IFERROR(E43/(E43+F43),0) -> 0.64772727 | H43: =IFERROR(AVERAGEIFS(Tickets!$H$2:$H$1201,Tickets!$J$2:$J$1201,$A43),0) -> 4
A44: 2026-05 | B44: =COUNTIF(Tickets!$J$2:$J$1201,$A44) -> 188 | C44: =B44/$B$4 -> 0.15666667 | D44: =IFERROR(AVERAGEIFS(Tickets!$K$2:$K$1201,Tickets!$J$2:$J$1201,$A44),0) -> 27.012394 | E44: =COUNTIFS(Tickets!$J$2:$J$1201,$A44,Tickets!$M$2:$M$1201,"Yes") -> 125 | F44: =COUNTIFS(Tickets!$J$2:$J$1201,$A44,Tickets!$M$2:$M$1201,"No") -> 63 | G44: =IFERROR(E44/(E44+F44),0) -> 0.66489362 | H44: =IFERROR(AVERAGEIFS(Tickets!$H$2:$H$1201,Tickets!$J$2:$J$1201,$A44),0) -> 3.8510638
A45: 2026-06 | B45: =COUNTIF(Tickets!$J$2:$J$1201,$A45) -> 185 | C45: =B45/$B$4 -> 0.15416667 | D45: =IFERROR(AVERAGEIFS(Tickets!$K$2:$K$1201,Tickets!$J$2:$J$1201,$A45),0) -> 28.931709 | E45: =COUNTIFS(Tickets!$J$2:$J$1201,$A45,Tickets!$M$2:$M$1201,"Yes") -> 102 | F45: =COUNTIFS(Tickets!$J$2:$J$1201,$A45,Tickets!$M$2:$M$1201,"No") -> 56 | G45: =IFERROR(E45/(E45+F45),0) -> 0.64556962 | H45: =IFERROR(AVERAGEIFS(Tickets!$H$2:$H$1201,Tickets!$J$2:$J$1201,$A45),0) -> 3.7974684

Sheet SLA Policy
A1: Priority | B1: SLA Target (hours)
A2: Critical | B2: 4 | D2: Blue/yellow cells are editable inputs; all KPIs recalculate.
A3: High | B3: 8 | D3: Targets are illustrative, typical of ITIL-style help-desk SLAs.
A4: Medium | B4: 24
A5: Low | B5: 72
